{'age': 50, 'edu_level': 2, 'marital_status': 2, 'INE_coincidence': 2, 'housing_time': 5, 'housing_mates': 2, 'housing_type': 2, 'eco_dependents': 3, 'prev_occupation': 3, 'other_source_income': 2, 'registered_time': 3, 'driving_time': 3, 'plat_type': 2, 'earnings': 2, 'plat_score': 4.3, 'anger_exp': 9, 'vio_criteria': 2, 'legal_back': 1, 'anger_mgmt': 6, 'default_tendency': 8, 'strong_words': 8, 'time_effort_inv': 6, 'quick_anger': 6, 'keeping_objs': 8, 'steal_tendency': 8, 'get_job_done': 6, 'unconcerned': 9, 'unthink_tendency': 6, 'lie_tendency': 10, 'disregard_tendency': 8, 'enjoys_adrenaline': 8, 'enjoys_fast_driving': 9, 'drives_fast': 6, 'took_time_respond': 1, 'stable_profile': 2, 'pasive_agresive_profile': 2, 'impulsive_profile': 6}
['Denegado']
"POST /model/getAcceptance HTTP/1.1" 200 18679
{'age': 50, 'edu_level': 2, 'marital_status': 2, 'INE_coincidence': 2, 'housing_time': 5, 'housing_mates': 2, 'housing_type': 2, 'eco_dependents': 3, 'prev_occupation': 3, 'other_source_income': 2, 'registered_time': 3, 'driving_time': 3, 'plat_type': 2, 'earnings': 2, 'plat_score': 4.3, 'anger_exp': 9, 'vio_criteria': 2, 'legal_back': 1, 'anger_mgmt': 6, 'default_tendency': 8, 'strong_words': 8, 'time_effort_inv': 6, 'quick_anger': 6, 'keeping_objs': 8, 'steal_tendency': 8, 'get_job_done': 6, 'unconcerned': 9, 'unthink_tendency': 6, 'lie_tendency': 10, 'disregard_tendency': 8, 'enjoys_adrenaline': 8, 'enjoys_fast_driving': 9, 'drives_fast': 6, 'took_time_respond': 1, 'stable_profile': 2, 'pasive_agresive_profile': 2, 'impulsive_profile': 6}
['Denegado']
"POST /model/getAcceptance HTTP/1.1" 200 18688
/code/model/views.py changed, reloading.
Watching for file changes with StatReloader
/code/model/views.py changed, reloading.
Watching for file changes with StatReloader
['Denegado']
"POST /model/getAcceptance HTTP/1.1" 200 18688
['Denegado']
"POST /model/getAcceptance HTTP/1.1" 200 18721
"GET /static/zavic/bootstrap-4.6.1-dist/js/bootstrap.min.js.map HTTP/1.1" 200 187646
"GET /static/zavic/bootstrap-4.6.1-dist/css/bootstrap.min.css.map HTTP/1.1" 200 653535
['Denegado']
"POST /model/getAcceptance HTTP/1.1" 200 18740
"GET /static/zavic/bootstrap-4.6.1-dist/js/bootstrap.min.js.map HTTP/1.1" 200 187646
"GET /static/zavic/bootstrap-4.6.1-dist/css/bootstrap.min.css.map HTTP/1.1" 200 653535
['Denegado']
"POST /model/getAcceptance HTTP/1.1" 200 18745
/code/model/views.py changed, reloading.
Watching for file changes with StatReloader
"GET /model/ HTTP/1.1" 200 700
"GET /model/register HTTP/1.1" 200 22373
2
Internal Server Error: /model/sendvars
Traceback (most recent call last):
  File "/usr/local/lib/python3.10/site-packages/django/core/handlers/exception.py", line 47, in inner
    response = get_response(request)
  File "/usr/local/lib/python3.10/site-packages/django/core/handlers/base.py", line 181, in _get_response
    response = wrapped_callback(request, *callback_args, **callback_kwargs)
  File "/code/model/views.py", line 117, in send_variables
    data["result"] = result
NameError: name 'data' is not defined
"POST /model/sendvars HTTP/1.1" 500 66067
/code/model/views.py changed, reloading.
Watching for file changes with StatReloader
2
Internal Server Error: /model/sendvars
Traceback (most recent call last):
  File "/usr/local/lib/python3.10/site-packages/django/db/backends/utils.py", line 84, in _execute
    return self.cursor.execute(sql, params)
psycopg2.errors.UniqueViolation: duplicate key value violates unique constraint "model_profilevariables_pkey"
DETAIL:  Key (customer_id)=(d03abad9-a64f-4eeb-85f3-91b11dfbf2a3) already exists.


The above exception was the direct cause of the following exception:

Traceback (most recent call last):
  File "/usr/local/lib/python3.10/site-packages/django/core/handlers/exception.py", line 47, in inner
    response = get_response(request)
  File "/usr/local/lib/python3.10/site-packages/django/core/handlers/base.py", line 181, in _get_response
    response = wrapped_callback(request, *callback_args, **callback_kwargs)
  File "/code/model/views.py", line 87, in send_variables
    profile.save()
  File "/usr/local/lib/python3.10/site-packages/django/db/models/base.py", line 739, in save
    self.save_base(using=using, force_insert=force_insert,
  File "/usr/local/lib/python3.10/site-packages/django/db/models/base.py", line 776, in save_base
    updated = self._save_table(
  File "/usr/local/lib/python3.10/site-packages/django/db/models/base.py", line 881, in _save_table
    results = self._do_insert(cls._base_manager, using, fields, returning_fields, raw)
  File "/usr/local/lib/python3.10/site-packages/django/db/models/base.py", line 919, in _do_insert
    return manager._insert(
  File "/usr/local/lib/python3.10/site-packages/django/db/models/manager.py", line 85, in manager_method
    return getattr(self.get_queryset(), name)(*args, **kwargs)
  File "/usr/local/lib/python3.10/site-packages/django/db/models/query.py", line 1270, in _insert
    return query.get_compiler(using=using).execute_sql(returning_fields)
  File "/usr/local/lib/python3.10/site-packages/django/db/models/sql/compiler.py", line 1416, in execute_sql
    cursor.execute(sql, params)
  File "/usr/local/lib/python3.10/site-packages/django/db/backends/utils.py", line 98, in execute
    return super().execute(sql, params)
  File "/usr/local/lib/python3.10/site-packages/django/db/backends/utils.py", line 66, in execute
    return self._execute_with_wrappers(sql, params, many=False, executor=self._execute)
  File "/usr/local/lib/python3.10/site-packages/django/db/backends/utils.py", line 75, in _execute_with_wrappers
    return executor(sql, params, many, context)
  File "/usr/local/lib/python3.10/site-packages/django/db/backends/utils.py", line 79, in _execute
    with self.db.wrap_database_errors:
  File "/usr/local/lib/python3.10/site-packages/django/db/utils.py", line 90, in __exit__
    raise dj_exc_value.with_traceback(traceback) from exc_value
  File "/usr/local/lib/python3.10/site-packages/django/db/backends/utils.py", line 84, in _execute
    return self.cursor.execute(sql, params)
django.db.utils.IntegrityError: duplicate key value violates unique constraint "model_profilevariables_pkey"
DETAIL:  Key (customer_id)=(d03abad9-a64f-4eeb-85f3-91b11dfbf2a3) already exists.

"POST /model/sendvars HTTP/1.1" 500 158134
2
Internal Server Error: /model/sendvars
Traceback (most recent call last):
  File "/usr/local/lib/python3.10/site-packages/django/core/handlers/exception.py", line 47, in inner
    response = get_response(request)
  File "/usr/local/lib/python3.10/site-packages/django/core/handlers/base.py", line 181, in _get_response
    response = wrapped_callback(request, *callback_args, **callback_kwargs)
  File "/code/model/views.py", line 118, in send_variables
    return JsonResponse({"result": result})
  File "/usr/local/lib/python3.10/site-packages/django/http/response.py", line 603, in __init__
    data = json.dumps(data, cls=encoder, **json_dumps_params)
  File "/usr/local/lib/python3.10/json/__init__.py", line 238, in dumps
    **kw).encode(obj)
  File "/usr/local/lib/python3.10/json/encoder.py", line 199, in encode
    chunks = self.iterencode(o, _one_shot=True)
  File "/usr/local/lib/python3.10/json/encoder.py", line 257, in iterencode
    return _iterencode(o, 0)
  File "/usr/local/lib/python3.10/site-packages/django/core/serializers/json.py", line 105, in default
    return super().default(o)
  File "/usr/local/lib/python3.10/json/encoder.py", line 179, in default
    raise TypeError(f'Object of type {o.__class__.__name__} '
TypeError: Object of type ndarray is not JSON serializable
"POST /model/sendvars HTTP/1.1" 500 91929
/code/model/views.py changed, reloading.
Watching for file changes with StatReloader
2
Internal Server Error: /model/sendvars
Traceback (most recent call last):
  File "/usr/local/lib/python3.10/site-packages/django/db/backends/utils.py", line 84, in _execute
    return self.cursor.execute(sql, params)
psycopg2.errors.UniqueViolation: duplicate key value violates unique constraint "model_profilevariables_pkey"
DETAIL:  Key (customer_id)=(d03abad9-a64f-4eeb-85f3-91b11dfbf2a4) already exists.


The above exception was the direct cause of the following exception:

Traceback (most recent call last):
  File "/usr/local/lib/python3.10/site-packages/django/core/handlers/exception.py", line 47, in inner
    response = get_response(request)
  File "/usr/local/lib/python3.10/site-packages/django/core/handlers/base.py", line 181, in _get_response
    response = wrapped_callback(request, *callback_args, **callback_kwargs)
  File "/code/model/views.py", line 87, in send_variables
    profile.save()
  File "/usr/local/lib/python3.10/site-packages/django/db/models/base.py", line 739, in save
    self.save_base(using=using, force_insert=force_insert,
  File "/usr/local/lib/python3.10/site-packages/django/db/models/base.py", line 776, in save_base
    updated = self._save_table(
  File "/usr/local/lib/python3.10/site-packages/django/db/models/base.py", line 881, in _save_table
    results = self._do_insert(cls._base_manager, using, fields, returning_fields, raw)
  File "/usr/local/lib/python3.10/site-packages/django/db/models/base.py", line 919, in _do_insert
    return manager._insert(
  File "/usr/local/lib/python3.10/site-packages/django/db/models/manager.py", line 85, in manager_method
    return getattr(self.get_queryset(), name)(*args, **kwargs)
  File "/usr/local/lib/python3.10/site-packages/django/db/models/query.py", line 1270, in _insert
    return query.get_compiler(using=using).execute_sql(returning_fields)
  File "/usr/local/lib/python3.10/site-packages/django/db/models/sql/compiler.py", line 1416, in execute_sql
    cursor.execute(sql, params)
  File "/usr/local/lib/python3.10/site-packages/django/db/backends/utils.py", line 98, in execute
    return super().execute(sql, params)
  File "/usr/local/lib/python3.10/site-packages/django/db/backends/utils.py", line 66, in execute
    return self._execute_with_wrappers(sql, params, many=False, executor=self._execute)
  File "/usr/local/lib/python3.10/site-packages/django/db/backends/utils.py", line 75, in _execute_with_wrappers
    return executor(sql, params, many, context)
  File "/usr/local/lib/python3.10/site-packages/django/db/backends/utils.py", line 79, in _execute
    with self.db.wrap_database_errors:
  File "/usr/local/lib/python3.10/site-packages/django/db/utils.py", line 90, in __exit__
    raise dj_exc_value.with_traceback(traceback) from exc_value
  File "/usr/local/lib/python3.10/site-packages/django/db/backends/utils.py", line 84, in _execute
    return self.cursor.execute(sql, params)
django.db.utils.IntegrityError: duplicate key value violates unique constraint "model_profilevariables_pkey"
DETAIL:  Key (customer_id)=(d03abad9-a64f-4eeb-85f3-91b11dfbf2a4) already exists.

"POST /model/sendvars HTTP/1.1" 500 158224
2
Internal Server Error: /model/sendvars
Traceback (most recent call last):
  File "/usr/local/lib/python3.10/site-packages/django/core/handlers/exception.py", line 47, in inner
    response = get_response(request)
  File "/usr/local/lib/python3.10/site-packages/django/core/handlers/base.py", line 181, in _get_response
    response = wrapped_callback(request, *callback_args, **callback_kwargs)
  File "/code/model/views.py", line 118, in send_variables
    return JsonResponse(result)
  File "/usr/local/lib/python3.10/site-packages/django/http/response.py", line 596, in __init__
    raise TypeError(
TypeError: In order to allow non-dict objects to be serialized set the safe parameter to False.
"POST /model/sendvars HTTP/1.1" 500 71213
/code/model/views.py changed, reloading.
Watching for file changes with StatReloader
/code/model/views.py changed, reloading.
Watching for file changes with StatReloader
/code/model/views.py changed, reloading.
Watching for file changes with StatReloader
/code/model/views.py changed, reloading.
Watching for file changes with StatReloader
/code/model/views.py changed, reloading.
Watching for file changes with StatReloader
"GET /admin/model/profilevariables/ HTTP/1.1" 200 9134
"GET /admin/jsi18n/ HTTP/1.1" 200 3195
2
Internal Server Error: /model/sendvars
Traceback (most recent call last):
  File "/usr/local/lib/python3.10/site-packages/django/core/handlers/exception.py", line 47, in inner
    response = get_response(request)
  File "/usr/local/lib/python3.10/site-packages/django/core/handlers/base.py", line 181, in _get_response
    response = wrapped_callback(request, *callback_args, **callback_kwargs)
  File "/code/model/views.py", line 88, in send_variables
    return redirect(getAcceptance({"customer_id": profile.id}))
AttributeError: 'ProfileVariables' object has no attribute 'id'
"POST /model/sendvars HTTP/1.1" 500 64064
/code/model/views.py changed, reloading.
Watching for file changes with StatReloader
"GET /admin/model/profilevariables/ HTTP/1.1" 200 9475
"GET /admin/jsi18n/ HTTP/1.1" 200 3195
2
Internal Server Error: /model/sendvars
Traceback (most recent call last):
  File "/usr/local/lib/python3.10/site-packages/django/core/handlers/exception.py", line 47, in inner
    response = get_response(request)
  File "/usr/local/lib/python3.10/site-packages/django/core/handlers/base.py", line 181, in _get_response
    response = wrapped_callback(request, *callback_args, **callback_kwargs)
  File "/code/model/views.py", line 88, in send_variables
    return redirect(getAcceptance({"customer_id": profile.customer_id}))
TypeError: getAcceptance() missing 1 required positional argument: 'profile'
"POST /model/sendvars HTTP/1.1" 500 64084
/code/model/views.py changed, reloading.
Watching for file changes with StatReloader
"GET /static/zavic/bootstrap-4.6.1-dist/css/bootstrap.min.css HTTP/1.1" 200 162017
2
Internal Server Error: /model/sendvars
Traceback (most recent call last):
  File "/usr/local/lib/python3.10/site-packages/django/core/handlers/exception.py", line 47, in inner
    response = get_response(request)
  File "/usr/local/lib/python3.10/site-packages/django/core/handlers/base.py", line 181, in _get_response
    response = wrapped_callback(request, *callback_args, **callback_kwargs)
  File "/code/model/views.py", line 88, in send_variables
    return redirect(getAcceptance({"customer_id": profile.customer_id}))
  File "/code/model/views.py", line 101, in getAcceptance
    if (request.POST.get('customer_id') != ''):
AttributeError: 'dict' object has no attribute 'POST'
"POST /model/sendvars HTTP/1.1" 500 70405
/code/model/views.py changed, reloading.
Watching for file changes with StatReloader
2
['Denegado']
Internal Server Error: /model/sendvars
Traceback (most recent call last):
  File "/usr/local/lib/python3.10/site-packages/django/core/handlers/exception.py", line 47, in inner
    response = get_response(request)
  File "/usr/local/lib/python3.10/site-packages/django/core/handlers/base.py", line 181, in _get_response
    response = wrapped_callback(request, *callback_args, **callback_kwargs)
  File "/code/model/views.py", line 88, in send_variables
    return redirect(getAcceptance(request))
  File "/usr/local/lib/python3.10/site-packages/django/shortcuts.py", line 41, in redirect
    return redirect_class(resolve_url(to, *args, **kwargs))
  File "/usr/local/lib/python3.10/site-packages/django/shortcuts.py", line 130, in resolve_url
    return reverse(to, args=args, kwargs=kwargs)
  File "/usr/local/lib/python3.10/site-packages/django/urls/base.py", line 86, in reverse
    return resolver._reverse_with_prefix(view, prefix, *args, **kwargs)
  File "/usr/local/lib/python3.10/site-packages/django/urls/resolvers.py", line 698, in _reverse_with_prefix
    raise NoReverseMatch(msg)
django.urls.exceptions.NoReverseMatch: Reverse for '<HttpResponse status_code=200, "text/html; charset=utf-8">' not found. '<HttpResponse status_code=200, "text/html; charset=utf-8">' is not a valid view function or pattern name.
"POST /model/sendvars HTTP/1.1" 500 83032
/code/model/views.py changed, reloading.
Watching for file changes with StatReloader
/code/model/views.py changed, reloading.
Watching for file changes with StatReloader
/code/model/views.py changed, reloading.
Watching for file changes with StatReloader
/code/model/views.py changed, reloading.
Watching for file changes with StatReloader
"GET /admin/model/profilevariables/ HTTP/1.1" 200 10498
"GET /admin/jsi18n/ HTTP/1.1" 200 3195
"GET /admin/model/profilevariables/ HTTP/1.1" 200 10498
"GET /admin/jsi18n/ HTTP/1.1" 200 3195
2
Internal Server Error: /model/sendvars
Traceback (most recent call last):
  File "/usr/local/lib/python3.10/site-packages/django/db/models/fields/__init__.py", line 2434, in to_python
    return uuid.UUID(**{input_form: value})
  File "/usr/local/lib/python3.10/uuid.py", line 177, in __init__
    raise ValueError('badly formed hexadecimal UUID string')
ValueError: badly formed hexadecimal UUID string

During handling of the above exception, another exception occurred:

Traceback (most recent call last):
  File "/usr/local/lib/python3.10/site-packages/django/core/handlers/exception.py", line 47, in inner
    response = get_response(request)
  File "/usr/local/lib/python3.10/site-packages/django/core/handlers/base.py", line 181, in _get_response
    response = wrapped_callback(request, *callback_args, **callback_kwargs)
  File "/code/model/views.py", line 86, in send_variables
    profile.save()
  File "/usr/local/lib/python3.10/site-packages/django/db/models/base.py", line 739, in save
    self.save_base(using=using, force_insert=force_insert,
  File "/usr/local/lib/python3.10/site-packages/django/db/models/base.py", line 776, in save_base
    updated = self._save_table(
  File "/usr/local/lib/python3.10/site-packages/django/db/models/base.py", line 881, in _save_table
    results = self._do_insert(cls._base_manager, using, fields, returning_fields, raw)
  File "/usr/local/lib/python3.10/site-packages/django/db/models/base.py", line 919, in _do_insert
    return manager._insert(
  File "/usr/local/lib/python3.10/site-packages/django/db/models/manager.py", line 85, in manager_method
    return getattr(self.get_queryset(), name)(*args, **kwargs)
  File "/usr/local/lib/python3.10/site-packages/django/db/models/query.py", line 1270, in _insert
    return query.get_compiler(using=using).execute_sql(returning_fields)
  File "/usr/local/lib/python3.10/site-packages/django/db/models/sql/compiler.py", line 1415, in execute_sql
    for sql, params in self.as_sql():
  File "/usr/local/lib/python3.10/site-packages/django/db/models/sql/compiler.py", line 1358, in as_sql
    value_rows = [
  File "/usr/local/lib/python3.10/site-packages/django/db/models/sql/compiler.py", line 1359, in <listcomp>
    [self.prepare_value(field, self.pre_save_val(field, obj)) for field in fields]
  File "/usr/local/lib/python3.10/site-packages/django/db/models/sql/compiler.py", line 1359, in <listcomp>
    [self.prepare_value(field, self.pre_save_val(field, obj)) for field in fields]
  File "/usr/local/lib/python3.10/site-packages/django/db/models/sql/compiler.py", line 1300, in prepare_value
    value = field.get_db_prep_save(value, connection=self.connection)
  File "/usr/local/lib/python3.10/site-packages/django/db/models/fields/__init__.py", line 842, in get_db_prep_save
    return self.get_db_prep_value(value, connection=connection, prepared=False)
  File "/usr/local/lib/python3.10/site-packages/django/db/models/fields/__init__.py", line 2424, in get_db_prep_value
    value = self.to_python(value)
  File "/usr/local/lib/python3.10/site-packages/django/db/models/fields/__init__.py", line 2436, in to_python
    raise exceptions.ValidationError(
django.core.exceptions.ValidationError: ['“d03abad9-a64f-4eeb-85f3-91b11dfbf2a10” is not a valid UUID.']
"POST /model/sendvars HTTP/1.1" 500 160084
"GET /admin/model/profilevariables/d03abad9-a64f-4eeb-85f3-91b11dfbf2a9/change/ HTTP/1.1" 200 35059
"GET /admin/jsi18n/ HTTP/1.1" 200 3195
"GET /admin/model/profilevariables/d03abad9-a64f-4eeb-85f3-91b11dfbf2a9/delete/ HTTP/1.1" 200 6669
"POST /admin/model/profilevariables/d03abad9-a64f-4eeb-85f3-91b11dfbf2a9/delete/ HTTP/1.1" 302 0
"GET /admin/model/profilevariables/ HTTP/1.1" 200 10379
"GET /admin/jsi18n/ HTTP/1.1" 200 3195
"POST /admin/model/profilevariables/ HTTP/1.1" 200 8376
"POST /admin/model/profilevariables/ HTTP/1.1" 302 0
"GET /admin/model/profilevariables/ HTTP/1.1" 200 7917
"GET /admin/jsi18n/ HTTP/1.1" 200 3195
2
"POST /model/sendvars HTTP/1.1" 200 25
"GET /model/checkacc HTTP/1.1" 200 920
"POST /model/getAcceptance HTTP/1.1" 200 48
['Denegado']
"POST /model/getAcceptance HTTP/1.1" 200 18744
"GET /model/register HTTP/1.1" 200 22373
1
"POST /model/sendvars HTTP/1.1" 200 25
"GET /admin/model/profilevariables/d03abad9-a64f-4eeb-85f3-91b11dfbf2a1/change/ HTTP/1.1" 200 35060
"GET /admin/jsi18n/ HTTP/1.1" 200 3195
"GET /admin/model/profilevariables/ HTTP/1.1" 200 8452
"GET /model/ HTTP/1.1" 200 700
"GET /model/checkacc HTTP/1.1" 200 920
"POST /model/getAcceptance HTTP/1.1" 200 48
['Denegado']
"POST /model/getAcceptance HTTP/1.1" 200 18745
['Denegado']
"POST /model/getAcceptance HTTP/1.1" 200 18919
/code/model/views.py changed, reloading.
Watching for file changes with StatReloader
['Denegado']
"POST /model/getAcceptance HTTP/1.1" 200 19388
['Denegado']
"POST /model/getAcceptance HTTP/1.1" 200 19290
['Denegado']
"POST /model/getAcceptance HTTP/1.1" 200 19909
['Denegado']
Internal Server Error: /model/getAcceptance
Traceback (most recent call last):
  File "/usr/local/lib/python3.10/site-packages/django/template/base.py", line 470, in parse
    compile_func = self.tags[command]
KeyError: 'endfor'

During handling of the above exception, another exception occurred:

Traceback (most recent call last):
  File "/usr/local/lib/python3.10/site-packages/django/core/handlers/exception.py", line 47, in inner
    response = get_response(request)
  File "/usr/local/lib/python3.10/site-packages/django/core/handlers/base.py", line 181, in _get_response
    response = wrapped_callback(request, *callback_args, **callback_kwargs)
  File "/code/model/views.py", line 171, in getAcceptance
    return render(request, 'acceptance.html', data)
  File "/usr/local/lib/python3.10/site-packages/django/shortcuts.py", line 19, in render
    content = loader.render_to_string(template_name, context, request, using=using)
  File "/usr/local/lib/python3.10/site-packages/django/template/loader.py", line 61, in render_to_string
    template = get_template(template_name, using=using)
  File "/usr/local/lib/python3.10/site-packages/django/template/loader.py", line 15, in get_template
    return engine.get_template(template_name)
  File "/usr/local/lib/python3.10/site-packages/django/template/backends/django.py", line 34, in get_template
    return Template(self.engine.get_template(template_name), self)
  File "/usr/local/lib/python3.10/site-packages/django/template/engine.py", line 143, in get_template
    template, origin = self.find_template(template_name)
  File "/usr/local/lib/python3.10/site-packages/django/template/engine.py", line 125, in find_template
    template = loader.get_template(name, skip=skip)
  File "/usr/local/lib/python3.10/site-packages/django/template/loaders/base.py", line 29, in get_template
    return Template(
  File "/usr/local/lib/python3.10/site-packages/django/template/base.py", line 155, in __init__
    self.nodelist = self.compile_nodelist()
  File "/usr/local/lib/python3.10/site-packages/django/template/base.py", line 193, in compile_nodelist
    return parser.parse()
  File "/usr/local/lib/python3.10/site-packages/django/template/base.py", line 478, in parse
    raise self.error(token, e)
  File "/usr/local/lib/python3.10/site-packages/django/template/base.py", line 476, in parse
    compiled_result = compile_func(self, token)
  File "/usr/local/lib/python3.10/site-packages/django/template/defaulttags.py", line 817, in do_for
    nodelist_loop = parser.parse(('empty', 'endfor',))
  File "/usr/local/lib/python3.10/site-packages/django/template/base.py", line 478, in parse
    raise self.error(token, e)
  File "/usr/local/lib/python3.10/site-packages/django/template/base.py", line 476, in parse
    compiled_result = compile_func(self, token)
  File "/usr/local/lib/python3.10/site-packages/django/template/defaulttags.py", line 968, in do_if
    nodelist = parser.parse(('elif', 'else', 'endif'))
  File "/usr/local/lib/python3.10/site-packages/django/template/base.py", line 472, in parse
    self.invalid_block_tag(token, command, parse_until)
  File "/usr/local/lib/python3.10/site-packages/django/template/base.py", line 522, in invalid_block_tag
    raise self.error(
django.template.exceptions.TemplateSyntaxError: Invalid block tag on line 119: 'endfor', expected 'elif', 'else' or 'endif'. Did you forget to register or load this tag?
"POST /model/getAcceptance HTTP/1.1" 500 186334
['Denegado']
"POST /model/getAcceptance HTTP/1.1" 200 20164
['Denegado']
"POST /model/getAcceptance HTTP/1.1" 200 22278
"GET /model/register HTTP/1.1" 200 22373
"GET /admin/model/profilevariables/ HTTP/1.1" 200 8452
"GET /static/admin/css/base.css HTTP/1.1" 304 0
"GET /static/admin/css/nav_sidebar.css HTTP/1.1" 304 0
"GET /static/admin/css/changelists.css HTTP/1.1" 304 0
"GET /static/admin/js/vendor/jquery/jquery.js HTTP/1.1" 304 0
"GET /static/admin/css/responsive.css HTTP/1.1" 304 0
"GET /static/admin/css/fonts.css HTTP/1.1" 304 0
"GET /static/admin/js/jquery.init.js HTTP/1.1" 304 0
"GET /static/admin/js/core.js HTTP/1.1" 304 0
"GET /static/admin/js/urlify.js HTTP/1.1" 304 0
"GET /static/admin/js/admin/RelatedObjectLookups.js HTTP/1.1" 304 0
"GET /static/admin/js/prepopulate.js HTTP/1.1" 304 0
"GET /static/admin/js/actions.js HTTP/1.1" 304 0
"GET /static/admin/js/vendor/xregexp/xregexp.js HTTP/1.1" 304 0
"GET /static/admin/js/nav_sidebar.js HTTP/1.1" 304 0
"GET /admin/jsi18n/ HTTP/1.1" 200 3195
"GET /static/admin/img/icon-addlink.svg HTTP/1.1" 304 0
"GET /static/admin/fonts/Roboto-Regular-webfont.woff HTTP/1.1" 304 0
"GET /static/admin/fonts/Roboto-Light-webfont.woff HTTP/1.1" 304 0
"GET /static/admin/fonts/Roboto-Bold-webfont.woff HTTP/1.1" 304 0
"GET /static/admin/img/tooltag-add.svg HTTP/1.1" 304 0
2
Internal Server Error: /model/sendvars
Traceback (most recent call last):
  File "/usr/local/lib/python3.10/site-packages/django/core/handlers/exception.py", line 47, in inner
    response = get_response(request)
  File "/usr/local/lib/python3.10/site-packages/django/core/handlers/base.py", line 181, in _get_response
    response = wrapped_callback(request, *callback_args, **callback_kwargs)
  File "/code/model/views.py", line 115, in send_variables
    result = model.predict(df)
  File "/usr/local/lib/python3.10/site-packages/sklearn/tree/_classes.py", line 505, in predict
    X = self._validate_X_predict(X, check_input)
  File "/usr/local/lib/python3.10/site-packages/sklearn/tree/_classes.py", line 471, in _validate_X_predict
    X = self._validate_data(X, dtype=DTYPE, accept_sparse="csr", reset=False)
  File "/usr/local/lib/python3.10/site-packages/sklearn/base.py", line 577, in _validate_data
    X = check_array(X, input_name="X", **check_params)
  File "/usr/local/lib/python3.10/site-packages/sklearn/utils/validation.py", line 899, in check_array
    _assert_all_finite(
  File "/usr/local/lib/python3.10/site-packages/sklearn/utils/validation.py", line 146, in _assert_all_finite
    raise ValueError(msg_err)
ValueError: Input X contains NaN.
DecisionTreeClassifier does not accept missing values encoded as NaN natively. For supervised learning, you might want to consider sklearn.ensemble.HistGradientBoostingClassifier and Regressor which accept missing values encoded as NaNs natively. Alternatively, it is possible to preprocess the data, for instance by using an imputer transformer in a pipeline or drop samples with missing values. See https://scikit-learn.org/stable/modules/impute.html You can find a list of all estimators that handle NaN values at the following page: https://scikit-learn.org/stable/modules/impute.html#estimators-that-handle-nan-values
"POST /model/sendvars HTTP/1.1" 500 97405
/code/model/views.py changed, reloading.
Watching for file changes with StatReloader
2
Internal Server Error: /model/sendvars
Traceback (most recent call last):
  File "/usr/local/lib/python3.10/site-packages/django/db/backends/utils.py", line 84, in _execute
    return self.cursor.execute(sql, params)
psycopg2.errors.UniqueViolation: duplicate key value violates unique constraint "model_profilevariables_pkey"
DETAIL:  Key (customer_id)=(00004415-1552-455f-99fc-7512b72aaae4) already exists.


The above exception was the direct cause of the following exception:

Traceback (most recent call last):
  File "/usr/local/lib/python3.10/site-packages/django/core/handlers/exception.py", line 47, in inner
    response = get_response(request)
  File "/usr/local/lib/python3.10/site-packages/django/core/handlers/base.py", line 181, in _get_response
    response = wrapped_callback(request, *callback_args, **callback_kwargs)
  File "/code/model/views.py", line 86, in send_variables
    profile.save()
  File "/usr/local/lib/python3.10/site-packages/django/db/models/base.py", line 739, in save
    self.save_base(using=using, force_insert=force_insert,
  File "/usr/local/lib/python3.10/site-packages/django/db/models/base.py", line 776, in save_base
    updated = self._save_table(
  File "/usr/local/lib/python3.10/site-packages/django/db/models/base.py", line 881, in _save_table
    results = self._do_insert(cls._base_manager, using, fields, returning_fields, raw)
  File "/usr/local/lib/python3.10/site-packages/django/db/models/base.py", line 919, in _do_insert
    return manager._insert(
  File "/usr/local/lib/python3.10/site-packages/django/db/models/manager.py", line 85, in manager_method
    return getattr(self.get_queryset(), name)(*args, **kwargs)
  File "/usr/local/lib/python3.10/site-packages/django/db/models/query.py", line 1270, in _insert
    return query.get_compiler(using=using).execute_sql(returning_fields)
  File "/usr/local/lib/python3.10/site-packages/django/db/models/sql/compiler.py", line 1416, in execute_sql
    cursor.execute(sql, params)
  File "/usr/local/lib/python3.10/site-packages/django/db/backends/utils.py", line 98, in execute
    return super().execute(sql, params)
  File "/usr/local/lib/python3.10/site-packages/django/db/backends/utils.py", line 66, in execute
    return self._execute_with_wrappers(sql, params, many=False, executor=self._execute)
  File "/usr/local/lib/python3.10/site-packages/django/db/backends/utils.py", line 75, in _execute_with_wrappers
    return executor(sql, params, many, context)
  File "/usr/local/lib/python3.10/site-packages/django/db/backends/utils.py", line 79, in _execute
    with self.db.wrap_database_errors:
  File "/usr/local/lib/python3.10/site-packages/django/db/utils.py", line 90, in __exit__
    raise dj_exc_value.with_traceback(traceback) from exc_value
  File "/usr/local/lib/python3.10/site-packages/django/db/backends/utils.py", line 84, in _execute
    return self.cursor.execute(sql, params)
django.db.utils.IntegrityError: duplicate key value violates unique constraint "model_profilevariables_pkey"
DETAIL:  Key (customer_id)=(00004415-1552-455f-99fc-7512b72aaae4) already exists.

"POST /model/sendvars HTTP/1.1" 500 158266
2
Internal Server Error: /model/sendvars
Traceback (most recent call last):
  File "/usr/local/lib/python3.10/site-packages/django/core/handlers/exception.py", line 47, in inner
    response = get_response(request)
  File "/usr/local/lib/python3.10/site-packages/django/core/handlers/base.py", line 181, in _get_response
    response = wrapped_callback(request, *callback_args, **callback_kwargs)
  File "/code/model/views.py", line 115, in send_variables
    result = model.predict(df)
  File "/usr/local/lib/python3.10/site-packages/sklearn/tree/_classes.py", line 505, in predict
    X = self._validate_X_predict(X, check_input)
  File "/usr/local/lib/python3.10/site-packages/sklearn/tree/_classes.py", line 471, in _validate_X_predict
    X = self._validate_data(X, dtype=DTYPE, accept_sparse="csr", reset=False)
  File "/usr/local/lib/python3.10/site-packages/sklearn/base.py", line 577, in _validate_data
    X = check_array(X, input_name="X", **check_params)
  File "/usr/local/lib/python3.10/site-packages/sklearn/utils/validation.py", line 899, in check_array
    _assert_all_finite(
  File "/usr/local/lib/python3.10/site-packages/sklearn/utils/validation.py", line 146, in _assert_all_finite
    raise ValueError(msg_err)
ValueError: Input X contains NaN.
DecisionTreeClassifier does not accept missing values encoded as NaN natively. For supervised learning, you might want to consider sklearn.ensemble.HistGradientBoostingClassifier and Regressor which accept missing values encoded as NaNs natively. Alternatively, it is possible to preprocess the data, for instance by using an imputer transformer in a pipeline or drop samples with missing values. See https://scikit-learn.org/stable/modules/impute.html You can find a list of all estimators that handle NaN values at the following page: https://scikit-learn.org/stable/modules/impute.html#estimators-that-handle-nan-values
"POST /model/sendvars HTTP/1.1" 500 97405
"GET /admin/model/profilevariables/ HTTP/1.1" 200 9134
"GET /admin/jsi18n/ HTTP/1.1" 200 3195
"POST /admin/model/profilevariables/ HTTP/1.1" 200 6971
"GET /static/admin/js/cancel.js HTTP/1.1" 304 0
"POST /admin/model/profilevariables/ HTTP/1.1" 302 0
"GET /admin/model/profilevariables/ HTTP/1.1" 200 8600
"GET /admin/jsi18n/ HTTP/1.1" 200 3195
"GET /static/admin/img/icon-yes.svg HTTP/1.1" 304 0
/code/model/views.py changed, reloading.
Watching for file changes with StatReloader
